let calculate = function(n){
    if (n > 10) {throw new Error('n should be less than 10')};
    return n + 10;
};

/* calculate(15) */

try {
    calculate(15)
} catch (e) {                               //автоматически создаётся объект ошибки и передаётся в catch. В нём есть свойства: name, message, с ними можно взаимодействовать
    console.log(e.name)
} finally {
    
}

//Инструкция throw позволяет генерировать исключения, определяемые пользователем. При этом выполнение текущей функции будет остановлено (инструкции после throw не будут выполнены), и управление будет передано в первый блок catch в стеке вызовов. Если catch блоков среди вызванных функций нет, выполнение программы будет остановлено.